
<robot name="homeplus_urdf">
  <link name="world"/>
  <joint name="base_x" type="prismatic">
    <parent link="world"/>
    <child link="base_x_link"/>
    <origin xyz="0 0 0" rpy="0 0 0"/>
    <axis xyz="1 0 0"/>
    <limit lower="-10" upper="10" effort="1000" velocity="1"/>
  </joint>
  <link name="base_x_link"/>
  <joint name="base_y" type="prismatic">
    <parent link="base_x_link"/>
    <child link="base_y_link"/>
    <origin xyz="0 0 0" rpy="0 0 0"/>
    <axis xyz="0 1 0"/>
    <limit lower="-10" upper="10" effort="1000" velocity="1"/>
  </joint>
  <link name="base_y_link"/>
  <joint name="base_theta" type="continuous">
    <parent link="base_y_link"/>
    <child link="base"/>
    <origin xyz="0 0 0" rpy="0 0 0"/>
    <axis xyz="0 0 1"/>
    <limit effort="1000" velocity="1"/>
  </joint>
  
  <link
    name="base">
    <inertial>
      <origin
        xyz="5.36687302959971E-07 5.36687301877503E-07 0.0698335734039721"
        rpy="0 0 0" />
      <mass
        value="1.93599733287841" />
      <inertia
        ixx="0.00763024520313416"
        ixy="5.63522720337791E-07"
        ixz="3.13778475181868E-09"
        iyy="0.0075494508667239"
        iyz="-3.13792658748242E-09"
        izz="0.002529154108625" />
    </inertial>
    <visual>
      <origin
        xyz="0 0 0"
        rpy="0 0 0" />
      <geometry>
        <mesh
          filename="package://homeplus_urdf/meshes/base.STL" />
      </geometry>
      <material
        name="">
        <color
          rgba="0.752941176470588 0.752941176470588 0.752941176470588 1" />
      </material>
    </visual>
    <collision>
      <origin
        xyz="0 0 0"
        rpy="0 0 0" />
      <geometry>
        <mesh
          filename="package://homeplus_urdf/meshes/base.STL" />
      </geometry>
    </collision>
  </link>
  <link
    name="Frame">
    <inertial>
      <origin
        xyz="0.201896542252744 0.079999090711498 -0.0342714033622425"
        rpy="0 0 0" />
      <mass
        value="3.29967833042039" />
      <inertia
        ixx="0.0339685155112727"
        ixy="2.44583411704264E-06"
        ixz="-0.000820229485495009"
        iyy="0.0344616286643939"
        iyz="4.66669647245987E-11"
        izz="0.00669916365911232" />
    </inertial>
    <visual>
      <origin
        xyz="0 0 0"
        rpy="0 0 0" />
      <geometry>
        <mesh
          filename="package://homeplus_urdf/meshes/Frame.STL" />
      </geometry>
      <material
        name="">
        <color
          rgba="0.752941176470588 0.752941176470588 0.752941176470588 1" />
      </material>
    </visual>
    <collision>
      <origin
        xyz="0 0 0"
        rpy="0 0 0" />
      <geometry>
        <mesh
          filename="package://homeplus_urdf/meshes/Frame.STL" />
      </geometry>
    </collision>
  </link>
  <joint
    name="JointFrame"
    type="prismatic">
    <origin
      xyz="-0.18 -0.08398 0.283"
      rpy="0 0 0" />
    <parent
      link="base" />
    <child
      link="Frame" />
    <axis
      xyz="0 0 -1" />
    <limit
      lower="-0.15"
      upper="0"
      effort="1"
      velocity="1" />
  </joint>
  <link
    name="Telescope">
    <inertial>
      <origin
        xyz="0.000771729818663525 0.000437143950816926 0.32581205885651"
        rpy="0 0 0" />
      <mass
        value="0.251949294795669" />
      <inertia
        ixx="0.0028564494284427"
        ixy="8.99971973485438E-11"
        ixz="-1.62769247516589E-09"
        iyy="0.0028616938969014"
        iyz="9.57986167138244E-08"
        izz="3.17904815416165E-05" />
    </inertial>
    <visual>
      <origin
        xyz="0 0 0"
        rpy="0 0 0" />
      <geometry>
        <mesh
          filename="package://homeplus_urdf/meshes/Telescope.STL" />
      </geometry>
      <material
        name="">
        <color
          rgba="0.752941176470588 0.752941176470588 0.752941176470588 1" />
      </material>
    </visual>
    <collision>
      <origin
        xyz="0 0 0"
        rpy="0 0 0" />
      <geometry>
        <mesh
          filename="package://homeplus_urdf/meshes/Telescope.STL" />
      </geometry>
    </collision>
  </link>
  <joint
    name="JointTelescope"
    type="prismatic">
    <origin
      xyz="0.285 0.08398 0.477"
      rpy="0 0 0" />
    <parent
      link="Frame" />
    <child
      link="Telescope" />
    <axis
      xyz="0 0 1" />
    <limit
      lower="-0.43"
      upper="0"
      effort="1"
      velocity="1" />
  </joint>
  <link
    name="Arm1">
    <inertial>
      <origin
        xyz="7.03186732800565E-07 0.0255523612247792 -0.327542637598859"
        rpy="0 0 0" />
      <mass
        value="0.142458692227375" />
      <inertia
        ixx="0.000647418154304748"
        ixy="-1.09262751252634E-10"
        ixz="-1.52692022508051E-09"
        iyy="0.000670896160414845"
        iyz="-9.61034332323993E-08"
        izz="4.06763543863988E-05" />
    </inertial>
    <visual>
      <origin
        xyz="0 0 0"
        rpy="0 0 0" />
      <geometry>
        <mesh
          filename="package://homeplus_urdf/meshes/Arm1.STL" />
      </geometry>
      <material
        name="">
        <color
          rgba="0.752941176470588 0.752941176470588 0.752941176470588 1" />
      </material>
    </visual>
    <collision>
      <origin
        xyz="0 0 0"
        rpy="0 0 0" />
      <geometry>
        <mesh
          filename="package://homeplus_urdf/meshes/Arm1.STL" />
      </geometry>
    </collision>
  </link>
  <joint
    name="JointArm1"
    type="revolute">
    <origin
      xyz="0 0.027951 0.52359"
      rpy="0 0 0" />
    <parent
      link="Telescope" />
    <child
      link="Arm1" />
    <axis
      xyz="0 1 0" />
    <limit
      lower="-3.229"
      upper="0"
      effort="1"
      velocity="1" />
  </joint>
  <link
    name="Arm2">
    <inertial>
      <origin
        xyz="0.326180191300973 -0.00821863696668879 -0.00108435548579178"
        rpy="0 0 0" />
      <mass
        value="0.116165417113753" />
      <inertia
        ixx="4.34271294343159E-05"
        ixy="1.09263208302466E-10"
        ixz="-9.61034328294376E-08"
        iyy="0.000506000098456717"
        iyz="1.52691916205519E-09"
        izz="0.000484496485361275" />
    </inertial>
    <visual>
      <origin
        xyz="0 0 0"
        rpy="0 0 0" />
      <geometry>
        <mesh
          filename="package://homeplus_urdf/meshes/Arm2.STL" />
      </geometry>
      <material
        name="">
        <color
          rgba="0.752941176470588 0.752941176470588 0.752941176470588 1" />
      </material>
    </visual>
    <collision>
      <origin
        xyz="0 0 0"
        rpy="0 0 0" />
      <geometry>
        <mesh
          filename="package://homeplus_urdf/meshes/Arm2.STL" />
      </geometry>
    </collision>
  </link>
  <joint
    name="JointArm2"
    type="revolute">
    <origin
      xyz="0 0.0665 -0.44462"
      rpy="0 0 0" />
    <parent
      link="Arm1" />
    <child
      link="Arm2" />
    <axis
      xyz="0 1 0" />
    <limit
      lower="-2.932"
      upper="1.274"
      effort="1"
      velocity="1" />
  </joint>
  <link
    name="Wrist">
    <inertial>
      <origin
        xyz="0.0117062571339291 0.00862941102998893 -8.86973896019327E-05"
        rpy="0 0 0" />
      <mass
        value="0.036356105635106" />
      <inertia
        ixx="1.03216697493622E-05"
        ixy="1.12110608341157E-07"
        ixz="-3.68367916334307E-10"
        iyy="6.65835103821079E-06"
        iyz="4.40506548763357E-08"
        izz="6.10843807889853E-06" />
    </inertial>
    <visual>
      <origin
        xyz="0 0 0"
        rpy="0 0 0" />
      <geometry>
        <mesh
          filename="package://homeplus_urdf/meshes/Wrist.STL" />
      </geometry>
      <material
        name="">
        <color
          rgba="0.752941176470588 0.752941176470588 0.752941176470588 1" />
      </material>
    </visual>
    <collision>
      <origin
        xyz="0 0 0"
        rpy="0 0 0" />
      <geometry>
        <mesh
          filename="package://homeplus_urdf/meshes/Wrist.STL" />
      </geometry>
    </collision>
  </link>
  <joint
    name="JointWrist"
    type="revolute">
    <origin
      xyz="0.43131 -0.0175 -0.023935"
      rpy="0 0 0" />
    <parent
      link="Arm2" />
    <child
      link="Wrist" />
    <axis
      xyz="1 0 0" />
    <limit
      lower="-1.396"
      upper="1.396"
      effort="1"
      velocity="1" />
  </joint>
  <link
    name="Hand">
    <inertial>
      <origin
        xyz="0.0510402582004251 -0.0235637345559821 4.72955008490317E-14"
        rpy="0 0 0" />
      <mass
        value="0.0198930486204883" />
      <inertia
        ixx="1.31880310255355E-05"
        ixy="5.80338692958736E-21"
        ixz="1.01799957749087E-18"
        iyy="9.95405369555564E-06"
        iyz="1.16148691677084E-18"
        izz="1.17150350450448E-05" />
    </inertial>
    <visual>
      <origin
        xyz="0 0 0"
        rpy="0 0 0" />
      <geometry>
        <mesh
          filename="package://homeplus_urdf/meshes/Hand.STL" />
      </geometry>
      <material
        name="">
        <color
          rgba="0.752941176470588 0.752941176470588 0.752941176470588 1" />
      </material>
    </visual>
    <collision>
      <origin
        xyz="0 0 0"
        rpy="0 0 0" />
      <geometry>
        <mesh
          filename="package://homeplus_urdf/meshes/Hand.STL" />
      </geometry>
    </collision>
  </link>
  <joint
    name="JointHand"
    type="revolute">
    <origin
      xyz="0.0125 0.035169 -0.008735"
      rpy="0 0 0" />
    <parent
      link="Wrist" />
    <child
      link="Hand" />
    <axis
      xyz="0 1 0" />
    <limit
      lower="-1.309"
      upper="1.571"
      effort="1"
      velocity="1" />
  </joint>
  <link
    name="FingerL">
    <inertial>
      <origin
        xyz="0.0572851953498564 0.00785403945078497 -0.0264999999999671"
        rpy="0 0 0" />
      <mass
        value="0.00826272704561505" />
      <inertia
        ixx="4.81809601260989E-07"
        ixy="1.60741522805415E-07"
        ixz="-4.33190663108753E-18"
        iyy="6.50554791455488E-06"
        iyz="3.37721721064055E-19"
        izz="6.85916077370771E-06" />
    </inertial>
    <visual>
      <origin
        xyz="0 0 0"
        rpy="0 0 0" />
      <geometry>
        <mesh
          filename="package://homeplus_urdf/meshes/FingerL.STL" />
      </geometry>
      <material
        name="">
        <color
          rgba="0.752941176470588 0.752941176470588 0.752941176470588 1" />
      </material>
    </visual>
    <collision>
      <origin
        xyz="0 0 0"
        rpy="0 0 0" />
      <geometry>
        <mesh
          filename="package://homeplus_urdf/meshes/FingerL.STL" />
      </geometry>
    </collision>
  </link>
  <joint
    name="JointFingerL"
    type="revolute">
    <origin
      xyz="0.076 -0.012 0.025"
      rpy="0 0 0" />
    <parent
      link="Hand" />
    <child
      link="FingerL" />
    <axis
      xyz="0 0 1" />
    <limit
      lower="-0.262"
      upper="1.396"
      effort="1"
      velocity="1" />
  </joint>
  <link
    name="FingerR">
    <inertial>
      <origin
        xyz="0.0491196994318599 -0.00842733863706574 -0.0264999999999619"
        rpy="0 0 0" />
      <mass
        value="0.00654686444828128" />
      <inertia
        ixx="3.4194538169811E-07"
        ixy="2.52337256659967E-08"
        ixz="-1.92932713630196E-18"
        iyy="2.95686717954717E-06"
        iyz="1.9053902549396E-19"
        izz="3.22357202128123E-06" />
    </inertial>
    <visual>
      <origin
        xyz="0 0 0"
        rpy="0 0 0" />
      <geometry>
        <mesh
          filename="package://homeplus_urdf/meshes/FingerR.STL" />
      </geometry>
      <material
        name="">
        <color
          rgba="0.752941176470588 0.752941176470588 0.752941176470588 1" />
      </material>
    </visual>
    <collision>
      <origin
        xyz="0 0 0"
        rpy="0 0 0" />
      <geometry>
        <mesh
          filename="package://homeplus_urdf/meshes/FingerR.STL" />
      </geometry>
    </collision>
  </link>
  <joint
    name="JointFingerR"
    type="revolute">
    <origin
      xyz="0.076 -0.036 0.025"
      rpy="0 0 0" />
    <parent
      link="Hand" />
    <child
      link="FingerR" />
    <axis
      xyz="0 0 -1" />
    <limit
      lower="-0.262"
      upper="1.396"
      effort="1"
      velocity="1" />
    <mimic
      joint="JointFingerL"
      multiplier="1"
      offset="0" />
  </joint>
  <link
    name="WheelFL">
    <inertial>
      <origin
        xyz="-0.00221199790886903 -0.00203064277825026 -2.08166817117217E-17"
        rpy="0 0 0" />
      <mass
        value="0.024229926039893" />
      <inertia
        ixx="1.19080621671214E-05"
        ixy="3.92089420362736E-06"
        ixz="-5.75732396144862E-21"
        iyy="1.19080621671214E-05"
        iyz="-4.47858125197631E-21"
        izz="7.98716796349408E-06" />
    </inertial>
    <visual>
      <origin
        xyz="0 0 0"
        rpy="0 0 0" />
      <geometry>
        <mesh
          filename="package://homeplus_urdf/meshes/WheelFL.STL" />
      </geometry>
      <material
        name="">
        <color
          rgba="0.792156862745098 0.819607843137255 0.933333333333333 1" />
      </material>
    </visual>
    <collision>
      <origin
        xyz="0 0 0"
        rpy="0 0 0" />
      <geometry>
        <mesh
          filename="package://homeplus_urdf/meshes/WheelFL.STL" />
      </geometry>
    </collision>
  </link>
  <joint
    name="JointWheelFL"
    type="continuous">
    <origin
      xyz="0.19317 0.19299 -0.033"
      rpy="0 0 0" />
    <parent
      link="base" />
    <child
      link="WheelFL" />
    <axis
      xyz="0.70711 0.70711 0" />
    <limit
      effort="1"
      velocity="1" />
  </joint>
  <link
    name="WheelFR">
    <inertial>
      <origin
        xyz="-0.00212132034355968 0.00212132034355972 1.38777878078145E-17"
        rpy="0 0 0" />
      <mass
        value="0.024229926039893" />
      <inertia
        ixx="1.19080621671215E-05"
        ixy="-3.92089420362737E-06"
        ixz="1.64880775117558E-21"
        iyy="1.19080621671215E-05"
        iyz="-1.5934710140752E-21"
        izz="7.9871679634941E-06" />
    </inertial>
    <visual>
      <origin
        xyz="0 0 0"
        rpy="0 0 0" />
      <geometry>
        <mesh
          filename="package://homeplus_urdf/meshes/WheelFR.STL" />
      </geometry>
      <material
        name="">
        <color
          rgba="0.792156862745098 0.819607843137255 0.933333333333333 1" />
      </material>
    </visual>
    <collision>
      <origin
        xyz="0 0 0"
        rpy="0 0 0" />
      <geometry>
        <mesh
          filename="package://homeplus_urdf/meshes/WheelFR.STL" />
      </geometry>
    </collision>
  </link>
  <joint
    name="JointWheelFR"
    type="continuous">
    <origin
      xyz="0.19308 -0.19308 -0.033"
      rpy="0 0 0" />
    <parent
      link="base" />
    <child
      link="WheelFR" />
    <axis
      xyz="-0.70711 0.70711 0" />
    <limit
      effort="1"
      velocity="1" />
  </joint>
  <link
    name="WheelBL">
    <inertial>
      <origin
        xyz="0.00212132034355966 -0.00212132034355965 -6.93889390390723E-18"
        rpy="0 0 0" />
      <mass
        value="0.0242299260398929" />
      <inertia
        ixx="1.19080621671214E-05"
        ixy="-3.92089420362736E-06"
        ixz="-6.89559011753301E-21"
        iyy="1.19080621671215E-05"
        iyz="5.66640417014397E-21"
        izz="7.98716796349408E-06" />
    </inertial>
    <visual>
      <origin
        xyz="0 0 0"
        rpy="0 0 0" />
      <geometry>
        <mesh
          filename="package://homeplus_urdf/meshes/WheelBL.STL" />
      </geometry>
      <material
        name="">
        <color
          rgba="0.792156862745098 0.819607843137255 0.933333333333333 1" />
      </material>
    </visual>
    <collision>
      <origin
        xyz="0 0 0"
        rpy="0 0 0" />
      <geometry>
        <mesh
          filename="package://homeplus_urdf/meshes/WheelBL.STL" />
      </geometry>
    </collision>
  </link>
  <joint
    name="JointWheelBL"
    type="continuous">
    <origin
      xyz="-0.19308 0.19308 -0.033"
      rpy="0 0 0" />
    <parent
      link="base" />
    <child
      link="WheelBL" />
    <axis
      xyz="-0.70711 0.70711 0" />
    <limit
      effort="1"
      velocity="1" />
  </joint>
  <link
    name="WheelBR">
    <inertial>
      <origin
        xyz="0.00212132034355966 0.00212132034355961 0"
        rpy="0 0 0" />
      <mass
        value="0.0242299260398931" />
      <inertia
        ixx="1.19080621671215E-05"
        ixy="3.92089420362738E-06"
        ixz="-1.37844200497226E-22"
        iyy="1.19080621671215E-05"
        iyz="-1.37844200497228E-22"
        izz="7.98716796349412E-06" />
    </inertial>
    <visual>
      <origin
        xyz="0 0 0"
        rpy="0 0 0" />
      <geometry>
        <mesh
          filename="package://homeplus_urdf/meshes/WheelBR.STL" />
      </geometry>
      <material
        name="">
        <color
          rgba="0.792156862745098 0.819607843137255 0.933333333333333 1" />
      </material>
    </visual>
    <collision>
      <origin
        xyz="0 0 0"
        rpy="0 0 0" />
      <geometry>
        <mesh
          filename="package://homeplus_urdf/meshes/WheelBR.STL" />
      </geometry>
    </collision>
  </link>
  <joint
    name="JointWheelBR"
    type="continuous">
    <origin
      xyz="-0.193081475451951 -0.193081475451951 -0.033"
      rpy="0 0 0" />
    <parent
      link="base" />
    <child
      link="WheelBR" />
    <axis
      xyz="0.707106781186548 0.707106781186547 0" />
    <limit
      effort="1"
      velocity="1" />
  </joint>
</robot>